{"nbformat":4,"nbformat_minor":0,"metadata":{"colab":{"provenance":[],"gpuType":"T4","authorship_tag":"ABX9TyNLeaSIJ9FJTYBb0bHV2jIG"},"kernelspec":{"name":"python3","display_name":"Python 3"},"language_info":{"name":"python"},"accelerator":"GPU"},"cells":[{"cell_type":"code","execution_count":4,"metadata":{"colab":{"base_uri":"https://localhost:8080/"},"id":"lqr39STYD41v","executionInfo":{"status":"ok","timestamp":1691413059113,"user_tz":-330,"elapsed":1464,"user":{"displayName":"Vaidehi Pawar","userId":"10265133952918539757"}},"outputId":"2bd7ab14-f59f-4fa2-f953-d03cf501ec5b"},"outputs":[{"output_type":"stream","name":"stdout","text":["Collecting tensorflow-gpu\n","  Using cached tensorflow-gpu-2.12.0.tar.gz (2.6 kB)\n","  \u001b[1;31merror\u001b[0m: \u001b[1msubprocess-exited-with-error\u001b[0m\n","  \n","  \u001b[31m×\u001b[0m \u001b[32mpython setup.py egg_info\u001b[0m did not run successfully.\n","  \u001b[31m│\u001b[0m exit code: \u001b[1;36m1\u001b[0m\n","  \u001b[31m╰─>\u001b[0m See above for output.\n","  \n","  \u001b[1;35mnote\u001b[0m: This error originates from a subprocess, and is likely not a problem with pip.\n","  Preparing metadata (setup.py) ... \u001b[?25l\u001b[?25herror\n","\u001b[1;31merror\u001b[0m: \u001b[1mmetadata-generation-failed\u001b[0m\n","\n","\u001b[31m×\u001b[0m Encountered error while generating package metadata.\n","\u001b[31m╰─>\u001b[0m See above for output.\n","\n","\u001b[1;35mnote\u001b[0m: This is an issue with the package mentioned above, not pip.\n","\u001b[1;36mhint\u001b[0m: See above for details.\n"]}],"source":["!pip install tensorflow-gpu"]}]}